Workbook

Sheet 🏠 Dashboard
A1: 💎 RETIREMENT WEALTH PLANNER | Your Complete Financial Freedom Toolkit
A2: India Edition · All figures in Indian Rupees (₹)
A3: 📌 NAVIGATE YOUR WEALTH PLANNER — Click any sheet tab below
B4: ⏰ | D4: 💸 | F4: 🏠
B5: Retirement Age Predictor | D5: Cost of Delay Calculator | F5: SIP + Home Loan Impact
B6: Calculate your ideal retirement age | D6: See the price of procrastination | F6: Balance investments vs EMI burden
B8: → Go to '📊 Retirement Age' tab | D8: → Go to '💸 Cost of Delay' tab | F8: → Go to '🏠 SIP & Home Loan' tab
B11: 🗓 | D11: 🎯 | F11: 🏦
B12: Financial Freedom Date | D12: Goal Visualization Dashboard | F12: Family Financial Vault
B13: Find your exact FI date | D13: Track all financial goals in one place | F13: Secure family docs & nominees
B15: → Go to '🗓 Freedom Date' tab | D15: → Go to '🎯 Goal Dashboard' tab | F15: → Go to '🏦 Family Vault' tab
A19: 📊 QUICK SUMMARY — Pulls from your inputs across all sheets
B20: Current Age | C20: Retirement Age | D20: Years to Retire | E20: Monthly SIP | F20: Corpus at Retirement | G20: Financial Freedom Date
B21: ='📊 Retirement Age'!C5 -> 30 | C21: ='📊 Retirement Age'!C14 | D21: ='📊 Retirement Age'!C15 -> 28 | E21: ='🏠 SIP & Home Loan'!C5 -> 15000 | F21: ='📊 Retirement Age'!C22 -> 3.1214194e+08 | G21: ='🗓 Freedom Date'!C20 -> 2072.8882
A23: 💡 PRO TIPS: Blue cells = Your inputs | Black cells = Auto-calculated | All calculations use Indian tax-adjusted returns

Sheet 📊 Retirement Age
A1: ⏰ RETIREMENT AGE PREDICTOR
A2: Answer a few questions to find your optimal retirement age and corpus needed
B4: 📋 PERSONAL & FINANCIAL INPUTS | E4: 📈 RETIREMENT AGE SENSITIVITY TABLE
B5: Current Age (years) | C5: 30 | E5: Retire At Age | F5: Corpus Needed (₹)
B6: Expected Retirement Age | C6: 58 | E6: 45 | F6: =IF(E6<=$C$5,0,$C$8*((1+$C$9)^(E6-$C$5))*(12*(1-(1+$C$9)^(-($C$7-E6)))/($C$13-$C$9)*(1+$C$13))) -> 1.6668063e+08
B7: Life Expectancy (years) | C7: 85 | E7: 48 | F7: =IF(E7<=$C$5,0,$C$8*((1+$C$9)^(E7-$C$5))*(12*(1-(1+$C$9)^(-($C$7-E7)))/($C$13-$C$9)*(1+$C$13))) -> 194435566
B8: Current Monthly Expenses (₹) | C8: 60000 | E8: 50 | F8: =IF(E8<=$C$5,0,$C$8*((1+$C$9)^(E8-$C$5))*(12*(1-(1+$C$9)^(-($C$7-E8)))/($C$13-$C$9)*(1+$C$13))) -> 2.1493162e+08
B9: Expected Inflation Rate | C9: 0.06 | E9: 52 | F9: =IF(E9<=$C$5,0,$C$8*((1+$C$9)^(E9-$C$5))*(12*(1-(1+$C$9)^(-($C$7-E9)))/($C$13-$C$9)*(1+$C$13))) -> 2.3703281e+08
B10: Current Monthly Income (₹) | C10: 150000 | E10: 54 | F10: =IF(E10<=$C$5,0,$C$8*((1+$C$9)^(E10-$C$5))*(12*(1-(1+$C$9)^(-($C$7-E10)))/($C$13-$C$9)*(1+$C$13))) -> 2.6069392e+08
B11: Savings Rate (% of income) | C11: 0.3 | E11: 55 | F11: =IF(E11<=$C$5,0,$C$8*((1+$C$9)^(E11-$C$5))*(12*(1-(1+$C$9)^(-($C$7-E11)))/($C$13-$C$9)*(1+$C$13))) -> 2.7307695e+08
B12: Expected Investment Return | C12: 0.12 | E12: 56 | F12: =IF(E12<=$C$5,0,$C$8*((1+$C$9)^(E12-$C$5))*(12*(1-(1+$C$9)^(-($C$7-E12)))/($C$13-$C$9)*(1+$C$13))) -> 2.8580019e+08
B13: Post-Retirement Return | C13: 0.07 | E13: 57 | F13: =IF(E13<=$C$5,0,$C$8*((1+$C$9)^(E13-$C$5))*(12*(1-(1+$C$9)^(-($C$7-E13)))/($C$13-$C$9)*(1+$C$13))) -> 298834286
B14: 📊 CALCULATED RESULTS | E14: 58 | F14: =IF(E14<=$C$5,0,$C$8*((1+$C$9)^(E14-$C$5))*(12*(1-(1+$C$9)^(-($C$7-E14)))/($C$13-$C$9)*(1+$C$13))) -> 3.1214194e+08
B15: Years to Retirement | C15: =C6-C5 -> 28 | E15: 60 | F15: =IF(E15<=$C$5,0,$C$8*((1+$C$9)^(E15-$C$5))*(12*(1-(1+$C$9)^(-($C$7-E15)))/($C$13-$C$9)*(1+$C$13))) -> 3.3938166e+08
B16: Years in Retirement | C16: =C7-C6 -> 27 | E16: 62 | F16: =IF(E16<=$C$5,0,$C$8*((1+$C$9)^(E16-$C$5))*(12*(1-(1+$C$9)^(-($C$7-E16)))/($C$13-$C$9)*(1+$C$13))) -> 367011451
B17: Monthly Savings (₹) | C17: =C10*C11 -> 45000 | E17: 65 | F17: =IF(E17<=$C$5,0,$C$8*((1+$C$9)^(E17-$C$5))*(12*(1-(1+$C$9)^(-($C$7-E17)))/($C$13-$C$9)*(1+$C$13))) -> 4.0750528e+08
B18: Monthly Expenses at Retirement (₹) | C18: =C8*((1+C9)^C15) -> 306701.2
B19: Annual Expenses at Retirement (₹) | C19: =C18*12 -> 3680414.4 | E19: 📌 RULES OF THUMB
B20: Expenses Inflation-Adj Total (₹) | C20: =C19*(1-(1+C9)^(-C16))/(C13-C9)*((1+C13)) -> 3.1214194e+08 | E20: • 25x Rule: Corpus = 25× Annual Expenses
B21: Current Corpus Value (₹) | C21: =C10*C11*12*((1+C12)^C15-1)/C12*(1+C12) -> 1.1533469e+08 | E21: • 4% Rule: Withdraw max 4% per year
B22: Required Retirement Corpus (₹) | C22: =C20 -> 3.1214194e+08 | E22: • 100-Age Rule: Equity allocation %
B23: Corpus Surplus / (Deficit) (₹) | C23: =C21-C22 -> -1.9680726e+08 | E23: • Save at least 20-30% of income
B24: Savings Corpus at Retirement (₹) | C24: =C21 -> 1.1533469e+08 | E24: • Emergency fund = 6 months expenses
B25: Corpus as Monthly Income Years | C25: =C21/(C18*12) -> 31.337419 | E25: • Term insurance = 15-20× annual income
B26: =IF(C23>=0,"✅ On Track! Your savings plan is sufficient","⚠️ Gap detected! Increase savings rate or delay retirement") -> ⚠️ Gap detected! Increase savings rate or delay retirement | E26: • Review plan every 2 years

Sheet 💸 Cost of Delay
A1: 💸 COST OF DELAY CALCULATOR — Every Year Counts!
A2: Discover how much you lose by starting your SIP late — the compounding penalty in real ₹
B4: 📋 BASE INPUTS
B5: Monthly SIP Amount (₹) | C5: 10000
B6: Expected Annual Return | C6: 0.12
B7: Target Age for Corpus | C7: 60
B8: Current Age (to start) | C8: 40
B10: ⏳ DELAY PENALTY TABLE — Start at Different Ages
B11: Start Age | C11: Years to Invest | D11: Total Invested (₹) | E11: Corpus at 60 (₹) | F11: vs Starting at 25 (₹) | G11: Delay Cost %
B12: =$C$8 -> 40 | C12: =MAX(0,$C$7-B12) -> 20 | D12: =IF(B12<=$C$7,$C$5*12*($C$7-B12),0) -> 2400000 | E12: =IF(B12>=$C$7,0,$C$5*(((1+$C$6/12)^(($C$7-B12)*12)-1)/($C$6/12))*(1+$C$6/12)) -> 9991479.2 | F12: — | G12: BASE
B13: =$C$8+2 -> 42 | C13: =MAX(0,$C$7-B13) -> 18 | D13: =IF(B13<=$C$7,$C$5*12*($C$7-B13),0) -> 2160000 | E13: =IF(B13>=$C$7,0,$C$5*(((1+$C$6/12)^(($C$7-B13)*12)-1)/($C$6/12))*(1+$C$6/12)) -> 7654392.4 | F13: =E13-E12 -> -2337086.8 | G13: =IF(E12=0,0,(E13-E12)/E12) -> -0.23390799
B14: =$C$8+5 -> 45 | C14: =MAX(0,$C$7-B14) -> 15 | D14: =IF(B14<=$C$7,$C$5*12*($C$7-B14),0) -> 1800000 | E14: =IF(B14>=$C$7,0,$C$5*(((1+$C$6/12)^(($C$7-B14)*12)-1)/($C$6/12))*(1+$C$6/12)) -> 5045760 | F14: =E14-E12 -> -4945719.2 | G14: =IF(E12=0,0,(E14-E12)/E12) -> -0.49499369
B15: =$C$8+7 -> 47 | C15: =MAX(0,$C$7-B15) -> 13 | D15: =IF(B15<=$C$7,$C$5*12*($C$7-B15),0) -> 1560000 | E15: =IF(B15>=$C$7,0,$C$5*(((1+$C$6/12)^(($C$7-B15)*12)-1)/($C$6/12))*(1+$C$6/12)) -> 3759311.4 | F15: =E15-E12 -> -6232167.7 | G15: =IF(E12=0,0,(E15-E12)/E12) -> -0.62374826
B16: =$C$8+10 -> 50 | C16: =MAX(0,$C$7-B16) -> 10 | D16: =IF(B16<=$C$7,$C$5*12*($C$7-B16),0) -> 1200000 | E16: =IF(B16>=$C$7,0,$C$5*(((1+$C$6/12)^(($C$7-B16)*12)-1)/($C$6/12))*(1+$C$6/12)) -> 2323390.8 | F16: =E16-E12 -> -7668088.4 | G16: =IF(E12=0,0,(E16-E12)/E12) -> -0.76746278
B17: =$C$8+13 -> 53 | C17: =MAX(0,$C$7-B17) -> 7 | D17: =IF(B17<=$C$7,$C$5*12*($C$7-B17),0) -> 840000 | E17: =IF(B17>=$C$7,0,$C$5*(((1+$C$6/12)^(($C$7-B17)*12)-1)/($C$6/12))*(1+$C$6/12)) -> 1319790 | F17: =E17-E12 -> -8671689.2 | G17: =IF(E12=0,0,(E17-E12)/E12) -> -0.86790845
B18: =$C$8+15 -> 55 | C18: =MAX(0,$C$7-B18) -> 5 | D18: =IF(B18<=$C$7,$C$5*12*($C$7-B18),0) -> 600000 | E18: =IF(B18>=$C$7,0,$C$5*(((1+$C$6/12)^(($C$7-B18)*12)-1)/($C$6/12))*(1+$C$6/12)) -> 824863.67 | F18: =E18-E12 -> -9166615.5 | G18: =IF(E12=0,0,(E18-E12)/E12) -> -0.91744329
B19: =$C$8+17 -> 57 | C19: =MAX(0,$C$7-B19) -> 3 | D19: =IF(B19<=$C$7,$C$5*12*($C$7-B19),0) -> 360000 | E19: =IF(B19>=$C$7,0,$C$5*(((1+$C$6/12)^(($C$7-B19)*12)-1)/($C$6/12))*(1+$C$6/12)) -> 435076.47 | F19: =E19-E12 -> -9556402.7 | G19: =IF(E12=0,0,(E19-E12)/E12) -> -0.95645525
B20: =$C$8+20 -> 60 | C20: =MAX(0,$C$7-B20) -> 0 | D20: =IF(B20<=$C$7,$C$5*12*($C$7-B20),0) -> 0 | E20: =IF(B20>=$C$7,0,$C$5*(((1+$C$6/12)^(($C$7-B20)*12)-1)/($C$6/12))*(1+$C$6/12)) -> 0 | F20: =E20-E12 -> -9991479.2 | G20: =IF(E12=0,0,(E20-E12)/E12) -> -1
B21: =$C$8+23 -> 63 | C21: =MAX(0,$C$7-B21) -> 0 | D21: =IF(B21<=$C$7,$C$5*12*($C$7-B21),0) -> 0 | E21: =IF(B21>=$C$7,0,$C$5*(((1+$C$6/12)^(($C$7-B21)*12)-1)/($C$6/12))*(1+$C$6/12)) -> 0 | F21: =E21-E12 -> -9991479.2 | G21: =IF(E12=0,0,(E21-E12)/E12) -> -1
B22: =$C$8+25 -> 65 | C22: =MAX(0,$C$7-B22) -> 0 | D22: =IF(B22<=$C$7,$C$5*12*($C$7-B22),0) -> 0 | E22: =IF(B22>=$C$7,0,$C$5*(((1+$C$6/12)^(($C$7-B22)*12)-1)/($C$6/12))*(1+$C$6/12)) -> 0 | F22: =E22-E12 -> -9991479.2 | G22: =IF(E12=0,0,(E22-E12)/E12) -> -1
B24: =CONCATENATE("💥 Starting at ",TEXT(B17,"0")," instead of ",TEXT(B12,"0"),": You lose ₹",TEXT(E17-E12,"#,##0")," in corpus — ",TEXT((E17-E12)/E12*-1,"0.0%")," penalty!") -> 💥 Starting at 53 instead of 40: You lose ₹-8,671,689 in corpus — 86.8% penalty!
B26: =CONCATENATE("🔢 COMPOUNDING POWER: ₹",TEXT(C5,"#,##0"),"/month at ",TEXT(C6*100,"0"),"% p.a.") -> 🔢 COMPOUNDING POWER: ₹10,000/month at 12% p.a.
B27: 5 years | C27: ="₹"&TEXT($C$5*(((1+$C$6/12)^(5*12)-1)/($C$6/12))*(1+$C$6/12)/100000,"0.0")&"L corpus" -> ₹8.2L corpus | D27: ="₹"&TEXT($C$5*12*5/100000,"0.0")&"L invested" -> ₹6.0L invested | E27: ="Money grew "&TEXT($C$5*(((1+$C$6/12)^(5*12)-1)/($C$6/12))*(1+$C$6/12)/($C$5*12*5),"0.0")&"x!" -> Money grew 1.4x!
B28: 10 years | C28: ="₹"&TEXT($C$5*(((1+$C$6/12)^(10*12)-1)/($C$6/12))*(1+$C$6/12)/100000,"0.0")&"L corpus" -> ₹23.2L corpus | D28: ="₹"&TEXT($C$5*12*10/100000,"0.0")&"L invested" -> ₹12.0L invested | E28: ="Money grew "&TEXT($C$5*(((1+$C$6/12)^(10*12)-1)/($C$6/12))*(1+$C$6/12)/($C$5*12*10),"0.0")&"x!" -> Money grew 1.9x!
B29: 15 years | C29: ="₹"&TEXT($C$5*(((1+$C$6/12)^(15*12)-1)/($C$6/12))*(1+$C$6/12)/100000,"0.0")&"L corpus" -> ₹50.5L corpus | D29: ="₹"&TEXT($C$5*12*15/100000,"0.0")&"L invested" -> ₹18.0L invested | E29: ="Money grew "&TEXT($C$5*(((1+$C$6/12)^(15*12)-1)/($C$6/12))*(1+$C$6/12)/($C$5*12*15),"0.0")&"x!" -> Money grew 2.8x!
B30: 20 years | C30: ="₹"&TEXT($C$5*(((1+$C$6/12)^(20*12)-1)/($C$6/12))*(1+$C$6/12)/100000,"0.0")&"L corpus" -> ₹99.9L corpus | D30: ="₹"&TEXT($C$5*12*20/100000,"0.0")&"L invested" -> ₹24.0L invested | E30: ="Money grew "&TEXT($C$5*(((1+$C$6/12)^(20*12)-1)/($C$6/12))*(1+$C$6/12)/($C$5*12*20),"0.0")&"x!" -> Money grew 4.2x!
B31: 25 years | C31: ="₹"&TEXT($C$5*(((1+$C$6/12)^(25*12)-1)/($C$6/12))*(1+$C$6/12)/100000,"0.0")&"L corpus" -> ₹189.8L corpus | D31: ="₹"&TEXT($C$5*12*25/100000,"0.0")&"L invested" -> ₹30.0L invested | E31: ="Money grew "&TEXT($C$5*(((1+$C$6/12)^(25*12)-1)/($C$6/12))*(1+$C$6/12)/($C$5*12*25),"0.0")&"x!" -> Money grew 6.3x!
B32: 30 years | C32: ="₹"&TEXT($C$5*(((1+$C$6/12)^(30*12)-1)/($C$6/12))*(1+$C$6/12)/100000,"0.0")&"L corpus" -> ₹353.0L corpus | D32: ="₹"&TEXT($C$5*12*30/100000,"0.0")&"L invested" -> ₹36.0L invested | E32: ="Money grew "&TEXT($C$5*(((1+$C$6/12)^(30*12)-1)/($C$6/12))*(1+$C$6/12)/($C$5*12*30),"0.0")&"x!" -> Money grew 9.8x!
B33: 35 years | C33: ="₹"&TEXT($C$5*(((1+$C$6/12)^(35*12)-1)/($C$6/12))*(1+$C$6/12)/100000,"0.0")&"L corpus" -> ₹649.5L corpus | D33: ="₹"&TEXT($C$5*12*35/100000,"0.0")&"L invested" -> ₹42.0L invested | E33: ="Money grew "&TEXT($C$5*(((1+$C$6/12)^(35*12)-1)/($C$6/12))*(1+$C$6/12)/($C$5*12*35),"0.0")&"x!" -> Money grew 15.5x!

Sheet 🏠 SIP & Home Loan
A1: 🏠 SIP + HOME LOAN IMPACT CALCULATOR
A2: Compare: What happens when you take a home loan vs continue pure SIP investments?
B4: 📈 SIP CALCULATOR INPUTS | E4: 🏡 HOME LOAN INPUTS
B5: Monthly SIP Amount (₹) | C5: 15000 | E5: Home Loan Amount (₹) | F5: 5000000
B6: SIP Annual Return (%) | C6: 0.12 | E6: Loan Interest Rate (Annual %) | F6: 0.0875
B7: SIP Duration (Years) | C7: 20 | E7: Loan Tenure (Years) | F7: 20
B8: Step-up Rate (Annual %) | C8: 0.1 | E8: Down Payment (₹) | F8: 1000000
E9: Property Appreciation Rate | F9: 0.06
B10: 📊 SIP RESULTS (Without Home Loan) | E10: 📊 HOME LOAN RESULTS
B11: Simple SIP Corpus (₹) | C11: =C5*(((1+C6/12)^(C7*12)-1)/(C6/12))*(1+C6/12) -> 14987219 | E11: Monthly EMI (₹) | F11: =F5*(F6/12*(1+F6/12)^(F7*12))/((1+F6/12)^(F7*12)-1) -> 44185.535
B12: Total Amount Invested (₹) | C12: =C5*12*C7 -> 3600000 | E12: Total Amount Paid (₹) | F12: =F11*F7*12 -> 10604529
B13: Wealth Gain (₹) | C13: =C11-C12 -> 11387219 | E13: Total Interest Paid (₹) | F13: =F12-F5 -> 5604528.5
B14: Step-up SIP Corpus (₹) | C14: =C5*12*((((1+C6)^C7-(1+C8)^C7))/(C6-C8))*(1+C6) -> 29421435 | E14: Property Value at Maturity (₹) | F14: =F5*(1+F9)^F7 -> 16035677
B15: Return Multiple | C15: =C11/(C5*12*C7) -> 4.1631163 | E15: Net Property Gain (₹) | F15: =F14-(F5+F8+F13) -> 4431148.9
E16: SIP if EMI invested instead (₹) | F16: =F11*(((1+C6/12)^(F7*12)-1)/(C6/12))*(1+C6/12) -> 44147886
E17: SIP Advantage over Property (₹) | F17: =F16-F15 -> 39716737
B19: ⚖️ COMBINED STRATEGY: SIP + HOME LOAN
B20: Total Monthly Outflow (₹) | C20: =C5+F11 -> 59185.535
B21: SIP Corpus (20 years) | C21: =C11 -> 14987219
B22: Property Net Value (20 years) | C22: =F14-F13 -> 10431149
B23: Combined Wealth (₹) | C23: =C21+C22 -> 25418368
B24: Tax Benefit (Home Loan 80C+24b, ₹/yr) | C24: 200000
B25: Effective EMI After Tax (₹/month) | C25: =(F11*12-C24)/12 -> 27518.869
B26: =IF(C23>(C11+F14),"✅ Balanced approach beats pure SIP by ₹"&TEXT(C23-C11,"#,##0"),"📊 Review strategy — pure SIP may be better") -> 📊 Review strategy — pure SIP may be better

Sheet 🗓 Freedom Date
A1: 🗓 FINANCIAL FREEDOM DATE CALCULATOR
A2: Calculate the exact date you achieve Financial Independence — never work for money again!
B4: 📋 YOUR FINANCIAL SNAPSHOT | E4: 📊 FI PROGRESS TRACKER
B5: Current Age | C5: 58 | E5: FI Target (₹) | F5: ='🗓 Freedom Date'!C16 -> 18000000
B6: Birth Year | C6: 1999 | E6: Current Net Worth (₹) | F6: ='🗓 Freedom Date'!C11 -> 1000000
B7: Current Monthly Expenses (₹) | C7: 60000 | E7: Remaining Gap (₹) | F7: =F5-F6 -> 17000000
B8: Expected Annual Inflation | C8: 0.06 | E8: % of FI Achieved | F8: =F6/F5 -> 0.055555556
B9: Annual Investment Return | C9: 0.12 | E9: Years Remaining (approx.) | F9: ='🗓 Freedom Date'!C18 -> 15.888249
B10: Post-FI Withdrawal Rate (4% rule) | C10: 0.04 | E10: Monthly ₹ saved toward FI | F10: ='🗓 Freedom Date'!C12 -> 30000
B11: Current Net Worth / Savings (₹) | C11: 1000000 | E11: FI Progress Milestone | F11: =IF(F8<0.25,"🌱 Early Stage",IF(F8<0.5,"🌿 Growing",IF(F8<0.75,"🌳 Halfway!",IF(F8<1,"🔥 Almost There!","🎊 FI ACHIEVED!")))) -> 🌱 Early Stage
B12: Monthly Savings / Investment (₹) | C12: 30000
B13: Annual Savings Step-up Rate | C13: 0.1 | E13: 💰 MONTHLY INCOME AT FI
E14: Annual Withdrawal (4% rule) (₹) | F14: =C16*0.04 -> 720000
B15: 🎯 FINANCIAL INDEPENDENCE CALCULATIONS | E15: Monthly Income at FI (₹) | F15: =F14/12 -> 60000
B16: FI Number (Required Corpus) (₹) | C16: =C7*12/C10 -> 18000000 | E16: Monthly Income (Inflation 10yr) (₹) | F16: =F15*(1+C8)^10 -> 107450.86
B17: FI Number (Inflation Adj. 20 yrs) (₹) | C17: =C7*12*(1+C8)^20/C10 -> 57728438 | E17: Monthly Income (Inflation 20yr) (₹) | F17: =F15*(1+C8)^20 -> 192428.13
B18: Years to FI (approx.) | C18: =LN((C16-C11)*(C9/12)/(C12)+1)/(LN(1+C9/12)*12) -> 15.888249 | E18: Safe FI Buffer (1.5x needed) (₹) | F18: =C16*1.5 -> 27000000
B19: Years to FI (Step-up SIP) | C19: =LN(C16*C9/(C12*12)+1)/LN(1+C9) -> 17.1705
B20: FI Achievement Year | C20: =(C6+C5)+C18 -> 2072.8882
B21: FI Age at Achievement | C21: =C20-C6 -> 73.888249
B23: =CONCATENATE("🎉 YOUR FINANCIAL FREEDOM DATE: ",CHOOSE(MIN(12,MAX(1,ROUND((C20-INT(C20))*12+1,0))),"January","February","March","April","May","June","July","August","September","October","November","December")," 1, ",TEXT(INT(C20),"0")," at age ",TEXT(C21,"0.0"),"!") -> 🎉 YOUR FINANCIAL FREEDOM DATE: December 1, 2072 at age 73.9!
B26: 🏆 FI MILESTONE TRACKER
B27: Milestone | D27: Example (₹60k/mo) | E27: Description
B28: 1× Monthly Expenses | D28: ="₹"&TEXT(C7/100000,"0.0")&"L" -> ₹0.6L | E28: Starter Emergency Fund
B29: 6× Monthly Expenses | D29: ="₹"&TEXT(C7*6/100000,"0.0")&"L" -> ₹3.6L | E29: Full Emergency Fund
B30: 25× Annual Expenses | D30: ="₹"&TEXT(C7*12*25/10000000,"0.00")&"Cr" -> ₹1.80Cr | E30: Lean FI Number
B31: 33× Annual Expenses | D31: ="₹"&TEXT(C7*12*33/10000000,"0.00")&"Cr" -> ₹2.38Cr | E31: Standard FI Number
B32: 40× Annual Expenses | D32: ="₹"&TEXT(C7*12*40/10000000,"0.00")&"Cr" -> ₹2.88Cr | E32: Fat FI / Safety Margin

Sheet 🎯 Goal Dashboard
A1: 🎯 GOAL VISUALIZATION DASHBOARD
A2: Track all your financial goals in one place — from emergencies to retirement
B4: 📋 FINANCIAL GOALS TRACKER
B5: Goal Name | C5: Target Amount (₹) | D5: Current Saved (₹) | E5: Monthly SIP (₹) | F5: Timeline (Yrs) | G5: % Achieved | H5: Status
B6: Emergency Fund | C6: 360000 | D6: 80000 | E6: 20000 | F6: 1 | G6: =D6/C6 -> 0.22222222 | H6: =IF(D6>=C6,"✅ Done!",IF(D6/C6>=0.75,"🔥 Almost!",IF(D6/C6>=0.5,"🌿 Half way",IF(D6/C6>=0.25,"🌱 Growing","🚀 Just Started")))) -> 🚀 Just Started
B7: Child Education | C7: 3000000 | D7: 200000 | E7: 15000 | F7: 10 | G7: =D7/C7 -> 0.066666667 | H7: =IF(D7>=C7,"✅ Done!",IF(D7/C7>=0.75,"🔥 Almost!",IF(D7/C7>=0.5,"🌿 Half way",IF(D7/C7>=0.25,"🌱 Growing","🚀 Just Started")))) -> 🚀 Just Started
B8: Home Down Payment | C8: 1500000 | D8: 300000 | E8: 25000 | F8: 4 | G8: =D8/C8 -> 0.2 | H8: =IF(D8>=C8,"✅ Done!",IF(D8/C8>=0.75,"🔥 Almost!",IF(D8/C8>=0.5,"🌿 Half way",IF(D8/C8>=0.25,"🌱 Growing","🚀 Just Started")))) -> 🚀 Just Started
B9: Car Purchase | C9: 800000 | D9: 100000 | E9: 12000 | F9: 3 | G9: =D9/C9 -> 0.125 | H9: =IF(D9>=C9,"✅ Done!",IF(D9/C9>=0.75,"🔥 Almost!",IF(D9/C9>=0.5,"🌿 Half way",IF(D9/C9>=0.25,"🌱 Growing","🚀 Just Started")))) -> 🚀 Just Started
B10: Foreign Vacation | C10: 200000 | D10: 30000 | E10: 5000 | F10: 2 | G10: =D10/C10 -> 0.15 | H10: =IF(D10>=C10,"✅ Done!",IF(D10/C10>=0.75,"🔥 Almost!",IF(D10/C10>=0.5,"🌿 Half way",IF(D10/C10>=0.25,"🌱 Growing","🚀 Just Started")))) -> 🚀 Just Started
B11: Child Marriage | C11: 2000000 | D11: 0 | E11: 8000 | F11: 18 | G11: =D11/C11 -> 0 | H11: =IF(D11>=C11,"✅ Done!",IF(D11/C11>=0.75,"🔥 Almost!",IF(D11/C11>=0.5,"🌿 Half way",IF(D11/C11>=0.25,"🌱 Growing","🚀 Just Started")))) -> 🚀 Just Started
B12: Parents Healthcare | C12: 500000 | D12: 100000 | E12: 5000 | F12: 5 | G12: =D12/C12 -> 0.2 | H12: =IF(D12>=C12,"✅ Done!",IF(D12/C12>=0.75,"🔥 Almost!",IF(D12/C12>=0.5,"🌿 Half way",IF(D12/C12>=0.25,"🌱 Growing","🚀 Just Started")))) -> 🚀 Just Started
B13: Business Capital | C13: 1000000 | D13: 150000 | E13: 10000 | F13: 3 | G13: =D13/C13 -> 0.15 | H13: =IF(D13>=C13,"✅ Done!",IF(D13/C13>=0.75,"🔥 Almost!",IF(D13/C13>=0.5,"🌿 Half way",IF(D13/C13>=0.25,"🌱 Growing","🚀 Just Started")))) -> 🚀 Just Started
B14: Retirement Corpus | C14: 30000000 | D14: 500000 | E14: 30000 | F14: 25 | G14: =D14/C14 -> 0.016666667 | H14: =IF(D14>=C14,"✅ Done!",IF(D14/C14>=0.75,"🔥 Almost!",IF(D14/C14>=0.5,"🌿 Half way",IF(D14/C14>=0.25,"🌱 Growing","🚀 Just Started")))) -> 🚀 Just Started
B15: Wealth Creation | C15: 5000000 | D15: 200000 | E15: 15000 | F15: 10 | G15: =D15/C15 -> 0.04 | H15: =IF(D15>=C15,"✅ Done!",IF(D15/C15>=0.75,"🔥 Almost!",IF(D15/C15>=0.5,"🌿 Half way",IF(D15/C15>=0.25,"🌱 Growing","🚀 Just Started")))) -> 🚀 Just Started
B16: 📊 TOTALS | C16: =SUM(C6:C15) -> 44360000 | D16: =SUM(D6:D15) -> 1660000 | E16: =SUM(E6:E15) -> 145000 | F16: =D16/C16 -> 0.0374211
B18: ⚡ GOAL PRIORITY MATRIX
B19: Goal | C19: Priority | D19: Urgency | E19: Impact | F19: Action
B20: Emergency Fund | C20: 🔴 Critical | D20: Immediate | E20: Protects Everything | F20: Build NOW
B21: Term Insurance | C21: 🔴 Critical | D21: Immediate | E21: Family Protection | F21: Buy NOW
B22: Retirement SIP | C22: 🔴 High | D22: Long Term | E22: Financial Freedom | F22: Start SIP
B23: Health Insurance | C23: 🔴 High | D23: Immediate | E23: Medical Safety Net | F23: Buy NOW
B24: Child Education | C24: 🟡 Medium | D24: 10-15 yrs | E24: Child's Future | F24: SIP Monthly
B25: Home Purchase | C25: 🟡 Medium | D25: 3-5 yrs | E25: Asset Creation | F25: Save Down
B26: Vacation/Car | C26: 🟢 Low | D26: 2-3 yrs | E26: Lifestyle | F26: Plan Ahead
B28: 💼 RECOMMENDED ASSET ALLOCATION
B29: Asset Class | C29: Allocation % | D29: Purpose | E29: Horizon | F29: Notes
B30: Equity (Mutual Funds) | C30: 40-60% | D30: High growth | E30: 10-15 yrs
B31: Debt (PPF, FD, Bonds) | C31: 20-30% | D31: Capital safety | E31: 1-5 yrs
B32: Real Estate | C32: 10-20% | D32: Appreciation + income | E32: 10+ yrs
B33: Gold / SGBs | C33: 5-10% | D33: Inflation hedge | E33: Long term
B34: Cash / Liquid | C34: 5-10% | D34: Emergency access | E34: 0-6 months
B35: International Funds | C35: 5-10% | D35: Global diversification | E35: 7+ yrs

Sheet 🏦 Family Vault
A1: 🏦 FAMILY FINANCIAL VAULT — Secure & Complete
A2: 🔐 Store all family financial details, nominee info, insurance policies & investments — CONFIDENTIAL
B4: 👨‍👩‍👧‍👦 FAMILY MEMBER DETAILS
B5: Name | C5: Relation | D5: DOB | E5: PAN Number | F5: Aadhaar (last 4) | G5: Blood Group
B6: Rajesh Kumar | C6: Self | D6: 15-Jan-1990 | E6: ABCDE1234F | F6: XXXX | G6: O+
B7: Priya Kumar | C7: Spouse | D7: 20-Mar-1993 | E7: PQRST5678G | F7: XXXX | G7: B+
B8: Arjun Kumar | C8: Son | D8: 10-Jun-2018 | E8: — | F8: XXXX | G8: O+
B9: Sunita Devi | C9: Mother | D9: 05-Aug-1960 | E9: LMNOP9012H | F9: XXXX | G9: A+
B10: ← Enter Details | C10: ← Enter Details | D10: ← Enter Details | E10: ← Enter Details | F10: ← Enter Details | G10: ← Enter Details
B11: ← Enter Details | C11: ← Enter Details | D11: ← Enter Details | E11: ← Enter Details | F11: ← Enter Details | G11: ← Enter Details
B13: 🛡️ INSURANCE POLICIES
B14: Policy Type | C14: Company | D14: Policy No. | E14: Sum Assured (₹) | F14: Premium/Year (₹) | G14: Maturity/Expiry
B15: Term Life Insurance | C15: LIC / HDFC Life | D15: TRM2024001 | E15: 15000000 | F15: 18000 | G15: 2060
B16: Health Insurance | C16: Star Health | D16: HLT2024002 | E16: 1000000 | F16: 25000 | G16: Annual Renewal
B17: Critical Illness | C17: HDFC ERGO | D17: CI2024003 | E17: 2500000 | F17: 12000 | G17: 2050
B18: Home Insurance | C18: Bajaj Allianz | D18: HOM2024004 | E18: 5000000 | F18: 8000 | G18: Annual Renewal
B19: Vehicle Insurance | C19: ICICI Lombard | D19: VEH2024005 | E19: 500000 | F19: 12000 | G19: Annual Renewal
B20: Personal Accident | C20: New India | D20: PA2024006 | E20: 2500000 | F20: 3000 | G20: Annual Renewal
B21: Total Life Cover (₹) | E21: =SUM(E15:E20) -> 26500000
B23: 📈 INVESTMENT PORTFOLIO
B24: Investment Type | C24: Scheme/Name | D24: Account/Folio No. | E24: Current Value (₹) | F24: Nominee | G24: Institution
B25: EPF / PF | C25: Employees Provident Fund | D25: PF12345678 | E25: 800000 | F25: Priya Kumar | G25: EPFO
B26: PPF | C26: Public Provident Fund | D26: PPF98765432 | E26: 450000 | F26: Priya Kumar | G26: SBI
B27: Mutual Fund - Equity | C27: Parag Parikh Flexi Cap | D27: MF1234567 | E27: 350000 | F27: Priya Kumar | G27: PPFAS AMC
B28: Mutual Fund - Debt | C28: HDFC Short Term Debt | D28: MF7654321 | E28: 200000 | F28: Priya Kumar | G28: HDFC AMC
B29: Direct Equity | C29: NSE/BSE Portfolio | D29: DEMAT001234 | E29: 600000 | F29: Priya Kumar | G29: Zerodha
B30: NPS | C30: National Pension Scheme | D30: NPS123456789 | E30: 250000 | F30: Priya Kumar | G30: SBI Pension
B31: FD / RD | C31: Fixed Deposit | D31: FD98765 | E31: 300000 | F31: Priya Kumar | G31: HDFC Bank
B32: Gold / SGB | C32: Sovereign Gold Bonds | D32: SGB2022-23 | E32: 150000 | F32: Priya Kumar | G32: RBI / NSE
B33: Real Estate | C33: Flat - Brigade Metropolis | D33: KA/BLR/2020 | E33: 8500000 | F33: Priya Kumar | G33: Brigade Group
B34: 📊 Total Portfolio Value (₹) | E34: =SUM(E25:E33) -> 11600000
B36: 📂 IMPORTANT DOCUMENTS CHECKLIST
B37: Document | C37: Location | D37: Last Updated | E37: Digital Copy | F37: Status
B38: Will / Testament | C38: Bank Locker / Advocate | D38: Jan 2024 | E38: Google Drive/Will | F38: ✅ Done
B39: Property Documents | C39: Bank Locker | D39: 2020 | E39: Google Drive/Property | F39: ✅ Done
B40: Aadhaar Cards | C40: Home Safe | D40: 2023 | E40: DigiLocker | F40: ✅ Done
B41: PAN Cards | C41: Home Safe | D41: 2020 | E41: DigiLocker | F41: ✅ Done
B42: Passports | C42: Home Safe | D42: 2022 | E42: Google Drive/Passports | F42: ✅ Done
B43: Marriage Certificate | C43: Home Safe | D43: 2019 | E43: Google Drive/Legal | F43: ✅ Done
B44: Birth Certificates | C44: Home Safe | D44: 2018 | E44: Google Drive/Legal | F44: ✅ Done
...
